2017-06-14 12:25:01 WARNING  golem.appconfig                     Can't open file /home/jholdsto/.local/share/golem/SimpleEnv/minilight.ini: [Errno 2] No such file or directory: '/home/jholdsto/.local/share/golem/SimpleEnv/minilight.ini'
2017-06-14 12:25:01 INFO     golem.client                        Client "", datadir: /home/jholdsto/.local/share/golem/default 
2017-06-14 12:25:02 WARNING  golem.docker.manager                Docker machine is not available: native Linux environment
2017-06-14 12:25:02 WARNING  golem.docker.manager                Docker: pulling image golemfactory/base:1.2
2017-06-14 12:25:29 WARNING  golem.docker.manager                Docker: pulling image golemfactory/blender:1.3
2017-06-14 12:26:12 WARNING  golem.docker.manager                Docker: pulling image golemfactory/luxrender:1.2
2017-06-14 12:26:26 INFO     golem.rpc.crossbar                  New node key pair generated! 
2017-06-14 12:26:26 INFO     golem.rpc.crossbar                  File permissions on node private key fixed! 
2017-06-14 12:26:26 INFO     golem.rpc.crossbar                  No extra node router roles 
2017-06-14 12:26:26 INFO     golem.rpc.crossbar                  Using default node shutdown triggers [u'shutdown_on_worker_exit'] 
2017-06-14 12:26:26 INFO     golem.rpc.crossbar                  Configuring node from local configuration ... 
2017-06-14 12:26:26 INFO     golem.rpc.crossbar                  Starting 1 workers ... 
2017-06-14 12:26:35 INFO     golem.rpc.crossbar                  Router 'worker-001': realm 'realm-001' (named 'golem') started 
2017-06-14 12:26:35 INFO     golem.rpc.crossbar                  Router 'worker-001': role 'role-001' (named 'anonymous') started on realm 'realm-001' 
2017-06-14 12:26:35 INFO     golem.rpc.crossbar                  Router 'worker-001': transport 'transport-001' started 
2017-06-14 12:26:35 INFO     golem.rpc.crossbar                  Local node configuration applied successfully! 
2017-06-14 12:26:35 INFO     golem.client                        Router session ready. Starting client... 
2017-06-14 12:26:35 INFO     golem.client                        Starting network ... 
2017-06-14 12:26:45 WARNING  golem.monitor.transport             Problem sending payload to: 'http://94.23.17.170:8881/'
Traceback (most recent call last):
  File "/home/mfrancis/Projects/golem/golem/monitor/transport/httptransport.py", line 15, in _post
  File "/home/mfrancis/Projects/golem/venv/lib/python2.7/site-packages/requests/api.py", line 110, in post
  File "/home/mfrancis/Projects/golem/venv/lib/python2.7/site-packages/requests/api.py", line 56, in request
  File "/home/mfrancis/Projects/golem/venv/lib/python2.7/site-packages/requests/sessions.py", line 488, in request
  File "/home/mfrancis/Projects/golem/venv/lib/python2.7/site-packages/requests/sessions.py", line 609, in send
  File "/home/mfrancis/Projects/golem/venv/lib/python2.7/site-packages/requests/adapters.py", line 479, in send
ConnectTimeout: HTTPConnectionPool(host='94.23.17.170', port=8881): Max retries exceeded with url: / (Caused by ConnectTimeoutError(<requests.packages.urllib3.connection.HTTPConnection object at 0x7fc8f7d05b90>, 'Connection to 94.23.17.170 timed out. (connect timeout=10)'))
2017-06-14 12:26:51 WARNING  golem.docker.manager                Docker machine is not available: native Linux environment
2017-06-14 12:26:52 ERROR    golem.task.taskthread               Task computing error: [Errno 13] Permission denied: '/home/jholdsto/.local/share/golem/default/task_tmp/work/params.py'
2017-06-14 12:26:52 WARNING  golem.task                          Failed to compute benchmark [Errno 13] Permission denied: '/home/jholdsto/.local/share/golem/default/task_tmp/work/params.py'
2017-06-14 12:26:52 ERROR    golem.task.taskcomputer             Unable to run blender benchmark: [Errno 13] Permission denied: '/home/jholdsto/.local/share/golem/default/task_tmp/work/params.py'
2017-06-14 12:26:53 INFO     golem.client                        Starting resource server ... 
2017-06-14 12:26:53 INFO     golem.client                        Starting p2p server ... 
2017-06-14 12:26:53 INFO     golem.client                        Starting task server ... 
2017-06-14 12:26:53 INFO     golem.client                        P2P server is listening on port 40102 
2017-06-14 12:26:53 INFO     golem.client                        Task server is listening on port 40103 
2017-06-14 12:26:54 WARNING  golem.monitor                       Port status: Local error: HTTPConnectionPool(host='94.23.17.170', port=8881): Max retries exceeded with url: /ping-me (Caused by ConnectTimeoutError(<requests.packages.urllib3.connection.HTTPConnection object at 0x7fc8f6403f50>, 'Connection to 94.23.17.170 timed out. (connect timeout=1)'))
2017-06-14 12:26:54 INFO     golem.client                        Starting GUI process... 
2017-06-14 12:26:54 INFO     golem.client                        Starting process monitor... 
2017-06-14 12:26:54 ERROR    golem.task.taskthread               Task computing error: [Errno 13] Permission denied: '/home/jholdsto/.local/share/golem/default/task_tmp/output/stdout.log'
2017-06-14 12:26:54 WARNING  golem.task                          Failed to compute benchmark [Errno 13] Permission denied: '/home/jholdsto/.local/share/golem/default/task_tmp/output/stdout.log'
2017-06-14 12:26:54 ERROR    golem.task.taskcomputer             Unable to run lux benchmark: [Errno 13] Permission denied: '/home/jholdsto/.local/share/golem/default/task_tmp/output/stdout.log'
2017-06-14 12:26:59 INFO     golem.network.transport.tcpnetwork  Connection failure. [Failure instance: Traceback (failure with no frames): <class 'twisted.internet.error.TimeoutError'>: User timeout caused connection failure.
]
2017-06-14 12:26:59 INFO     golem.network.p2p.p2pservice        Connection to peer failure None.
2017-06-14 12:26:59 INFO     golem.network.transport.tcpnetwork  Connection failure. [Failure instance: Traceback (failure with no frames): <class 'twisted.internet.error.TimeoutError'>: User timeout caused connection failure.
]
2017-06-14 12:26:59 INFO     golem.network.p2p.p2pservice        Connection to peer failure None.
2017-06-14 12:26:59 INFO     golem.network.transport.tcpnetwork  Connection failure. [Failure instance: Traceback (failure with no frames): <class 'twisted.internet.error.TimeoutError'>: User timeout caused connection failure.
]
2017-06-14 12:26:59 INFO     golem.network.p2p.p2pservice        Connection to peer failure None.
2017-06-14 12:26:59 INFO     golem.network.transport.tcpnetwork  Connection failure. [Failure instance: Traceback (failure with no frames): <class 'twisted.internet.error.TimeoutError'>: User timeout caused connection failure.
]
2017-06-14 12:26:59 INFO     golem.network.p2p.p2pservice        Connection to peer failure None.
2017-06-14 12:27:04 WARNING  golem.monitor.transport             Problem sending payload to: 'http://94.23.17.170:8881/'
Traceback (most recent call last):
  File "/home/mfrancis/Projects/golem/golem/monitor/transport/httptransport.py", line 15, in _post
  File "/home/mfrancis/Projects/golem/venv/lib/python2.7/site-packages/requests/api.py", line 110, in post
  File "/home/mfrancis/Projects/golem/venv/lib/python2.7/site-packages/requests/api.py", line 56, in request
  File "/home/mfrancis/Projects/golem/venv/lib/python2.7/site-packages/requests/sessions.py", line 488, in request
  File "/home/mfrancis/Projects/golem/venv/lib/python2.7/site-packages/requests/sessions.py", line 609, in send
  File "/home/mfrancis/Projects/golem/venv/lib/python2.7/site-packages/requests/adapters.py", line 479, in send
ConnectTimeout: HTTPConnectionPool(host='94.23.17.170', port=8881): Max retries exceeded with url: / (Caused by ConnectTimeoutError(<requests.packages.urllib3.connection.HTTPConnection object at 0x7fc8f6417550>, 'Connection to 94.23.17.170 timed out. (connect timeout=10)'))
2017-06-14 12:27:14 WARNING  golem.monitor.transport             Problem sending payload to: 'http://94.23.17.170:8881/'
Traceback (most recent call last):
  File "/home/mfrancis/Projects/golem/golem/monitor/transport/httptransport.py", line 15, in _post
  File "/home/mfrancis/Projects/golem/venv/lib/python2.7/site-packages/requests/api.py", line 110, in post
  File "/home/mfrancis/Projects/golem/venv/lib/python2.7/site-packages/requests/api.py", line 56, in request
  File "/home/mfrancis/Projects/golem/venv/lib/python2.7/site-packages/requests/sessions.py", line 488, in request
  File "/home/mfrancis/Projects/golem/venv/lib/python2.7/site-packages/requests/sessions.py", line 609, in send
  File "/home/mfrancis/Projects/golem/venv/lib/python2.7/site-packages/requests/adapters.py", line 479, in send
ConnectTimeout: HTTPConnectionPool(host='94.23.17.170', port=8881): Max retries exceeded with url: / (Caused by ConnectTimeoutError(<requests.packages.urllib3.connection.HTTPConnection object at 0x7fc8f7d33950>, 'Connection to 94.23.17.170 timed out. (connect timeout=10)'))
2017-06-14 12:27:24 WARNING  golem.monitor.transport             Problem sending payload to: 'http://94.23.17.170:8881/'
Traceback (most recent call last):
  File "/home/mfrancis/Projects/golem/golem/monitor/transport/httptransport.py", line 15, in _post
  File "/home/mfrancis/Projects/golem/venv/lib/python2.7/site-packages/requests/api.py", line 110, in post
  File "/home/mfrancis/Projects/golem/venv/lib/python2.7/site-packages/requests/api.py", line 56, in request
  File "/home/mfrancis/Projects/golem/venv/lib/python2.7/site-packages/requests/sessions.py", line 488, in request
  File "/home/mfrancis/Projects/golem/venv/lib/python2.7/site-packages/requests/sessions.py", line 609, in send
  File "/home/mfrancis/Projects/golem/venv/lib/python2.7/site-packages/requests/adapters.py", line 479, in send
ConnectTimeout: HTTPConnectionPool(host='94.23.17.170', port=8881): Max retries exceeded with url: / (Caused by ConnectTimeoutError(<requests.packages.urllib3.connection.HTTPConnection object at 0x7fc8f7d33810>, 'Connection to 94.23.17.170 timed out. (connect timeout=10)'))
